Workbook

Sheet CCTV
A1: 序号 | B1: 管道 | C1: 管材 | D1: 管段 | E1: 管径 | F1: 长度 | G1: 缺陷 | H1: 修复 | I1: 结构状况 | J1: 养护 | K1: 功能状况 | L1: 备注
B2: 类型 | E2: （mm） | F2: （m） | H2: 指数 | J2: 指数
H3: RI | J3: MI
A4: 1 | B4: 雨水主管 | C4: HDPE | D4: Y1A-Y1 | E4: 1200 | F4: 7 | G4: 无 | H4: 0 | I4: 一级 | J4: 0 | K4: 一级 | L4: ---
A5: 2 | B5: 雨水主管 | C5: HDPE | D5: Y1A-Y1B | E5: 1200 | F5: 9 | G5: 无 | H5: 0 | I5: 一级 | J5: 0 | K5: 一级 | L5: ---
A6: 3 | B6: 雨水主管 | C6: HDPE | D6: Y2-Y1B | E6: 1200 | F6: 27 | G6: 无 | H6: 0 | I6: 一级 | J6: 0 | K6: 一级 | L6: ---
A7: 4 | B7: 雨水主管 | C7: HDPE | D7: Y2-Y3 | E7: 1200 | F7: 21 | G7: 无 | H7: 0 | I7: 一级 | J7: 0 | K7: 一级 | L7: ---
A8: 5 | B8: 雨水主管 | C8: HDPE | D8: Y4-Y3 | E8: 1350 | F8: 34 | G8: 无 | H8: 0 | I8: 一级 | J8: 0 | K8: 一级 | L8: ---
A9: 6 | B9: 雨水主管 | C9: HDPE | D9: Y4-Y5 | E9: 1350 | F9: 38 | G9: 无 | H9: 0 | I9: 一级 | J9: 0 | K9: 一级 | L9: ---
B10: 雨水主管 | D10: Y6-Y5 | E10: 1000 | F10: 30
B11: 雨水主管 | D11: Y6-Y7 | E11: 1000 | F11: 30
B12: 雨水主管 | D12: Y8-Y7 | E12: 1000 | F12: 30
B13: 雨水主管 | D13: Y8-Y9 | E13: 1000 | F13: 27
B14: 雨水主管 | D14: Y10-Y9 | E14: 1000 | F14: 31
B15: 雨水主管 | D15: Y10-Y11 | E15: 1000 | F15: 28
B16: 雨水主管 | D16: Y12-Y11 | E16: 1000 | F16: 27
B17: 雨水主管 | D17: Y12-Y13 | E17: 1000 | F17: 37
B18: 雨水主管 | D18: Y14-Y13 | E18: 1000 | F18: 28
B19: 雨水主管 | D19: Y14-Y15 | E19: 1000 | F19: 18
B20: 雨水主管 | D20: Y16-Y5 | E20: 1000 | F20: 21
B21: 雨水主管 | D21: Y16-Y17 | E21: 1000 | F21: 68
... B45: 污水主管 | D45: W17-W18 | E45: 300 | F45: 32
B46: 雨水支管 | D46: Y1-N
B47: 雨水支管 | D47: Y1-S
B48: 雨水支管 | D48: Y2-2-1
B49: 雨水支管 | D49: Y2-n
B50: 雨水支管 | D50: Y2-s
B51: 雨水支管 | D51: Y3-E(2)
B52: 雨水支管 | D52: Y3-E
B53: 雨水支管 | D53: Y4-E
B54: 雨水支管 | D54: Y4-W
B55: 雨水支管 | D55: Y4-Y4-1
B56: 雨水支管 | D56: Y5-E
B57: 雨水支管 | D57: Y5-W
... B81: 污水支管 | D81: W9-9-1

Sheet Sheet2
A1: 管道编号 | B1: =VLOOKUP(B2,CCTV!A:D,4,0) -> Y1A-Y1
A2: 图 号 | B2: 1
A3: 缺陷名称 | B3: --
A4: 缺陷等级 | B4: --
A5: 距 离 | B5: --
A6: 时钟表示 | B6: --
A7: 备 注 | B7: 主管管道良好。 未发现结构性和功能性缺陷。 管道具体信息详见表4.2.1。
A9: 管道编号 | B9: =VLOOKUP(B10,CCTV!A:D,4,0) -> Y1A-Y1B
A10: 图 号 | B10: 2
A11: 缺陷名称 | B11: --
A12: 缺陷等级 | B12: --
A13: 距 离 | B13: --
A14: 时钟表示 | B14: --
A15: 备 注 | B15: 主管管道良好。 未发现结构性和功能性缺陷。 管道具体信息详见表4.2.1。
A17: 管道编号 | B17: =VLOOKUP(B18,CCTV!A:D,4,0) -> Y2-Y1B
A18: 图 号 | B18: 3
A19: 缺陷名称 | B19: --
A20: 缺陷等级 | B20: --
A21: 距 离 | B21: --
A22: 时钟表示 | B22: --
A23: 备 注 | B23: 主管管道良好。 未发现结构性和功能性缺陷。 管道具体信息详见表4.2.1。
A25: 管道编号 | B25: =VLOOKUP(B26,CCTV!A:D,4,0) -> Y2-Y3
A26: 图 号 | B26: 4
A27: 缺陷名称 | B27: --
A28: 缺陷等级 | B28: --
A29: 距 离 | B29: --
A30: 时钟表示 | B30: --
A31: 备 注 | B31: 主管管道良好。 未发现结构性和功能性缺陷。 管道具体信息详见表4.2.1。
A33: 管道编号 | B33: =VLOOKUP(B34,CCTV!A:D,4,0) -> Y4-Y3
A34: 图 号 | B34: 5
A35: 缺陷名称 | B35: --
A36: 缺陷等级 | B36: --
A37: 距 离 | B37: --
A38: 时钟表示 | B38: --
A39: 备 注 | B39: 主管管道良好。 未发现结构性和功能性缺陷。 管道具体信息详见表4.2.1。
A41: 管道编号 | B41: =VLOOKUP(B42,CCTV!A:D,4,0) -> Y4-Y5
A42: 图 号 | B42: 6
A43: 缺陷名称 | B43: --
A44: 缺陷等级 | B44: --
A45: 距 离 | B45: --
...
